Workbook

Sheet Top 8
A1: TOP 8 MOST PROFITABLE HERBLORE POTIONS (live)
A2: Last price update: 2026-09-15 03:03 UTC — auto-refreshes every 5 minutes (server.mjs). Source: wiki median GE price (buy=sell=median).
A3: Rank | B3: Potion | C3: Level | D3: XP | E3: Cost to make (per craft) | F3: Sell price (4) | G3: Profit / craft | H3: GP/h | I3: Equipment (0/1)
A4: 1 | B4: =IF($G4="","",INDEX(Recipes!$A$2:$A$55,MATCH($G4,Recipes!$R$2:$R$55,0))) -> Prayer regeneration potion(4) | C4: =IF($G4="","",INDEX(Recipes!$B$2:$B$55,MATCH($G4,Recipes!$R$2:$R$55,0))) -> 58 | D4: =IF($G4="","",INDEX(Recipes!$C$2:$C$55,MATCH($G4,Recipes!$R$2:$R$55,0))) -> 132 | E4: =IF($G4="","",INDEX(Recipes!$L$2:$L$55,MATCH($G4,Recipes!$R$2:$R$55,0))) -> 57078 | F4: =IF($G4="","",INDEX(Recipes!$M$2:$M$55,MATCH($G4,Recipes!$R$2:$R$55,0))) -> 68159 | G4: =IFERROR(LARGE(Recipes!$R$2:$R$55,1),"") -> 2716.225 | H4: =IF($G4="","",INDEX(Recipes!$Q$2:$Q$55,MATCH($G4,Recipes!$R$2:$R$55,0))) -> 8148675 | I4: Alchemist's amulet (15%: 4 doses instead of 3) | J4: 1
A5: 2 | B5: =IF($G5="","",INDEX(Recipes!$A$2:$A$55,MATCH($G5,Recipes!$R$2:$R$55,0))) -> Goading potion(4) | C5: =IF($G5="","",INDEX(Recipes!$B$2:$B$55,MATCH($G5,Recipes!$R$2:$R$55,0))) -> 54 | D5: =IF($G5="","",INDEX(Recipes!$C$2:$C$55,MATCH($G5,Recipes!$R$2:$R$55,0))) -> 132 | E5: =IF($G5="","",INDEX(Recipes!$L$2:$L$55,MATCH($G5,Recipes!$R$2:$R$55,0))) -> 49560 | F5: =IF($G5="","",INDEX(Recipes!$M$2:$M$55,MATCH($G5,Recipes!$R$2:$R$55,0))) -> 58337 | G5: =IFERROR(LARGE(Recipes!$R$2:$R$55,2),"") -> 2368.15 | H5: =IF($G5="","",INDEX(Recipes!$Q$2:$Q$55,MATCH($G5,Recipes!$R$2:$R$55,0))) -> 7104450 | I5: Prescription goggles (10%: secondary not consumed) | J5: 1
A6: 3 | B6: =IF($G6="","",INDEX(Recipes!$A$2:$A$55,MATCH($G6,Recipes!$R$2:$R$55,0))) -> Haemostatic poultice | C6: =IF($G6="","",INDEX(Recipes!$B$2:$B$55,MATCH($G6,Recipes!$R$2:$R$55,0))) -> 56 | D6: =IF($G6="","",INDEX(Recipes!$C$2:$C$55,MATCH($G6,Recipes!$R$2:$R$55,0))) -> 27 | E6: =IF($G6="","",INDEX(Recipes!$L$2:$L$55,MATCH($G6,Recipes!$R$2:$R$55,0))) -> 2411 | F6: =IF($G6="","",INDEX(Recipes!$M$2:$M$55,MATCH($G6,Recipes!$R$2:$R$55,0))) -> 3154 | G6: =IFERROR(LARGE(Recipes!$R$2:$R$55,3),"") -> 864.1 | H6: =IF($G6="","",INDEX(Recipes!$Q$2:$Q$55,MATCH($G6,Recipes!$R$2:$R$55,0))) -> 2592300
A7: 4 | B7: =IF($G7="","",INDEX(Recipes!$A$2:$A$55,MATCH($G7,Recipes!$R$2:$R$55,0))) -> Extended anti-venom+(4) | C7: =IF($G7="","",INDEX(Recipes!$B$2:$B$55,MATCH($G7,Recipes!$R$2:$R$55,0))) -> 94 | D7: =IF($G7="","",INDEX(Recipes!$C$2:$C$55,MATCH($G7,Recipes!$R$2:$R$55,0))) -> 80 | E7: =IF($G7="","",INDEX(Recipes!$L$2:$L$55,MATCH($G7,Recipes!$R$2:$R$55,0))) -> 14163.75 | F7: =IF($G7="","",INDEX(Recipes!$M$2:$M$55,MATCH($G7,Recipes!$R$2:$R$55,0))) -> 18171 | G7: =IFERROR(LARGE(Recipes!$R$2:$R$55,4),"") -> 862.125 | H7: =IF($G7="","",INDEX(Recipes!$Q$2:$Q$55,MATCH($G7,Recipes!$R$2:$R$55,0))) -> 2586375
A8: 5 | B8: =IF($G8="","",INDEX(Recipes!$A$2:$A$55,MATCH($G8,Recipes!$R$2:$R$55,0))) -> Super combat potion(4) | C8: =IF($G8="","",INDEX(Recipes!$B$2:$B$55,MATCH($G8,Recipes!$R$2:$R$55,0))) -> 90 | D8: =IF($G8="","",INDEX(Recipes!$C$2:$C$55,MATCH($G8,Recipes!$R$2:$R$55,0))) -> 150 | E8: =IF($G8="","",INDEX(Recipes!$L$2:$L$55,MATCH($G8,Recipes!$R$2:$R$55,0))) -> 11896 | F8: =IF($G8="","",INDEX(Recipes!$M$2:$M$55,MATCH($G8,Recipes!$R$2:$R$55,0))) -> 11968 | G8: =IFERROR(LARGE(Recipes!$R$2:$R$55,5),"") -> 445.7 | H8: =IF($G8="","",INDEX(Recipes!$Q$2:$Q$55,MATCH($G8,Recipes!$R$2:$R$55,0))) -> 1337100
A9: 6 | B9: =IF($G9="","",INDEX(Recipes!$A$2:$A$55,MATCH($G9,Recipes!$R$2:$R$55,0))) -> Prayer potion(4) | C9: =IF($G9="","",INDEX(Recipes!$B$2:$B$55,MATCH($G9,Recipes!$R$2:$R$55,0))) -> 38 | D9: =IF($G9="","",INDEX(Recipes!$C$2:$C$55,MATCH($G9,Recipes!$R$2:$R$55,0))) -> 87.5 | E9: =IF($G9="","",INDEX(Recipes!$L$2:$L$55,MATCH($G9,Recipes!$R$2:$R$55,0))) -> 7170 | F9: =IF($G9="","",INDEX(Recipes!$M$2:$M$55,MATCH($G9,Recipes!$R$2:$R$55,0))) -> 9473 | G9: =IFERROR(LARGE(Recipes!$R$2:$R$55,6),"") -> 279.175 | H9: =IF($G9="","",INDEX(Recipes!$Q$2:$Q$55,MATCH($G9,Recipes!$R$2:$R$55,0))) -> 837525
A10: 7 | B10: =IF($G10="","",INDEX(Recipes!$A$2:$A$55,MATCH($G10,Recipes!$R$2:$R$55,0))) -> Guthix balance(4) | C10: =IF($G10="","",INDEX(Recipes!$B$2:$B$55,MATCH($G10,Recipes!$R$2:$R$55,0))) -> 22 | D10: =IF($G10="","",INDEX(Recipes!$C$2:$C$55,MATCH($G10,Recipes!$R$2:$R$55,0))) -> 50 | E10: =IF($G10="","",INDEX(Recipes!$L$2:$L$55,MATCH($G10,Recipes!$R$2:$R$55,0))) -> 826.75 | F10: =IF($G10="","",INDEX(Recipes!$M$2:$M$55,MATCH($G10,Recipes!$R$2:$R$55,0))) -> 1124 | G10: =IFERROR(LARGE(Recipes!$R$2:$R$55,7),"") -> 110.55 | H10: =IF($G10="","",INDEX(Recipes!$Q$2:$Q$55,MATCH($G10,Recipes!$R$2:$R$55,0))) -> 331650
A11: 8 | B11: =IF($G11="","",INDEX(Recipes!$A$2:$A$55,MATCH($G11,Recipes!$R$2:$R$55,0))) -> Guthix rest(4) | C11: =IF($G11="","",INDEX(Recipes!$B$2:$B$55,MATCH($G11,Recipes!$R$2:$R$55,0))) -> 18 | D11: =IF($G11="","",INDEX(Recipes!$C$2:$C$55,MATCH($G11,Recipes!$R$2:$R$55,0))) -> 59 | E11: =IF($G11="","",INDEX(Recipes!$L$2:$L$55,MATCH($G11,Recipes!$R$2:$R$55,0))) -> 1942 | F11: =IF($G11="","",INDEX(Recipes!$M$2:$M$55,MATCH($G11,Recipes!$R$2:$R$55,0))) -> 2794 | G11: =IFERROR(LARGE(Recipes!$R$2:$R$55,8),"") -> 103.6 | H11: =IF($G11="","",INDEX(Recipes!$Q$2:$Q$55,MATCH($G11,Recipes!$R$2:$R$55,0))) -> 621600
A12: One craft = 3 doses; doses are fungible (2×(3) → (4)+(2)). Profit/craft = doses·(sell(4)+sell(2))/6 − (craft cost − 10%·goggles·secondary cost); doses = 3 + 15%·amulet for normal potions, 3 for guthix rest, 4 for always-4 potions (antidote+, antidote++, anti-venom+, super combat, super antifire) which sell as a (4) and are not amulet-boosted; the amulet does not work on components (haemostatic poultice, weapon poison); goggles don't save serum 207 ashes. Sell = after 2% GE tax (cap 5M). Set J4/J5 to 0 to rank without the equipment. Full list of all 54 potions on the Recipes sheet.

Sheet Recipes
A1: Potion | B1: Level | C1: XP | D1: Ingredient 1 | E1: Qty | F1: Ingredient 2 | G1: Qty | H1: Ingredient 3 | I1: Qty | J1: Ingredient 4 | K1: Qty | L1: Cost to make (per craft) | M1: Sell price (4) | N1: Sell price (2) | O1: Secondary cost (per craft) | P1: Profit / craft | Q1: GP/h | R1: Rank key (hidden)
A2: Attack potion(4) | B2: 3 | C2: 25 | D2: guam potion (unf) | E2: 1 | F2: Eye of newt | G2: 1 | L2: =IFERROR((IF($D2="","",VLOOKUP($D2,Prices!$A$2:$D$174,3,0))*$E2)+(IF($F2="","",VLOOKUP($F2,Prices!$A$2:$D$174,3,0))*$G2),"") -> 300 | M2: =IFERROR(VLOOKUP($A2,Prices!$A$2:$D$174,4,0),"") -> 9 | N2: =IF(ISNUMBER(SEARCH("(4)",$A2)),IFERROR(VLOOKUP(SUBSTITUTE($A2,"(4)","(2)"),Prices!$A$2:$D$174,4,0),""),"") -> 10 | O2: =IFERROR((IF($F2="","",VLOOKUP($F2,Prices!$A$2:$D$174,3,0))*$G2),"") -> 4 | P2: =IF(OR($L2="",$M2=""),"",(3+0.15*'Top 8'!$J$4)*($M2+$N2)/6-($L2-0.1*'Top 8'!$J$5*$O2)) -> -289.625 | Q2: =IF($P2="","",$P2*3000) -> -868875 | R2: =IF($P2="","",$P2+ROW()/1000000) -> -289.625
A3: Antipoison(4) | B3: 5 | C3: 37.5 | D3: marrentill potion (unf) | E3: 1 | F3: Unicorn horn dust | G3: 1 | L3: =IFERROR((IF($D3="","",VLOOKUP($D3,Prices!$A$2:$D$174,3,0))*$E3)+(IF($F3="","",VLOOKUP($F3,Prices!$A$2:$D$174,3,0))*$G3),"") -> 938 | M3: =IFERROR(VLOOKUP($A3,Prices!$A$2:$D$174,4,0),"") -> 444 | N3: =IF(ISNUMBER(SEARCH("(4)",$A3)),IFERROR(VLOOKUP(SUBSTITUTE($A3,"(4)","(2)"),Prices!$A$2:$D$174,4,0),""),"") -> 232 | O3: =IFERROR((IF($F3="","",VLOOKUP($F3,Prices!$A$2:$D$174,3,0))*$G3),"") -> 699 | P3: =IF(OR($L3="",$M3=""),"",(3+0.15*'Top 8'!$J$4)*($M3+$N3)/6-($L3-0.1*'Top 8'!$J$5*$O3)) -> -513.2 | Q3: =IF($P3="","",$P3*3000) -> -1539600 | R3: =IF($P3="","",$P3+ROW()/1000000) -> -513.2
A4: Strength potion(4) | B4: 12 | C4: 50 | D4: tarromin potion (unf) | E4: 1 | F4: Limpwurt root | G4: 1 | L4: =IFERROR((IF($D4="","",VLOOKUP($D4,Prices!$A$2:$D$174,3,0))*$E4)+(IF($F4="","",VLOOKUP($F4,Prices!$A$2:$D$174,3,0))*$G4),"") -> 705 | M4: =IFERROR(VLOOKUP($A4,Prices!$A$2:$D$174,4,0),"") -> 106 | N4: =IF(ISNUMBER(SEARCH("(4)",$A4)),IFERROR(VLOOKUP(SUBSTITUTE($A4,"(4)","(2)"),Prices!$A$2:$D$174,4,0),""),"") -> 43 | O4: =IFERROR((IF($F4="","",VLOOKUP($F4,Prices!$A$2:$D$174,3,0))*$G4),"") -> 221 | P4: =IF(OR($L4="",$M4=""),"",(3+0.15*'Top 8'!$J$4)*($M4+$N4)/6-($L4-0.1*'Top 8'!$J$5*$O4)) -> -604.675 | Q4: =IF($P4="","",$P4*3000) -> -1814025 | R4: =IF($P4="","",$P4+ROW()/1000000) -> -604.67499
A5: Serum 207 (4) | B5: 15 | C5: 50 | D5: tarromin potion (unf) | E5: 1 | F5: Ashes | G5: 1 | L5: =IFERROR((IF($D5="","",VLOOKUP($D5,Prices!$A$2:$D$174,3,0))*$E5)+(IF($F5="","",VLOOKUP($F5,Prices!$A$2:$D$174,3,0))*$G5),"") -> 519 | M5: =IFERROR(VLOOKUP($A5,Prices!$A$2:$D$174,4,0),"") -> 34 | N5: =IF(ISNUMBER(SEARCH("(4)",$A5)),IFERROR(VLOOKUP(SUBSTITUTE($A5,"(4)","(2)"),Prices!$A$2:$D$174,4,0),""),"") -> 9 | O5: =IFERROR((IF($F5="","",VLOOKUP($F5,Prices!$A$2:$D$174,3,0))*$G5),"") -> 35 | P5: =IF(OR($L5="",$M5=""),"",(3+0.15*'Top 8'!$J$4)*($M5+$N5)/6-($L5-0)) -> -496.425 | Q5: =IF($P5="","",$P5*3000) -> -1489275 | R5: =IF($P5="","",$P5+ROW()/1000000) -> -496.42499
A6: Guthix rest(4) | B6: 18 | C6: 59 | D6: Cup of hot water | E6: 1 | F6: Guam leaf | G6: 2 | H6: Harralander | I6: 1 | J6: Marrentill | K6: 1 | L6: =IFERROR((IF($D6="","",VLOOKUP($D6,Prices!$A$2:$D$174,3,0))*$E6)+(IF($F6="","",VLOOKUP($F6,Prices!$A$2:$D$174,3,0))*$G6)+(IF($H6="","",VLOOKUP($H6,Prices!$A$2:$D$174,3,0))*$I6)+(IF($J6="","",VLOOKUP($J6,Prices!$A$2:$D$174,3,0))*$K6),"") -> 1942 | M6: =IFERROR(VLOOKUP($A6,Prices!$A$2:$D$174,4,0),"") -> 2794 | N6: =IF(ISNUMBER(SEARCH("(4)",$A6)),IFERROR(VLOOKUP(SUBSTITUTE($A6,"(4)","(2)"),Prices!$A$2:$D$174,4,0),""),"") -> 1231 | O6: =IFERROR((IF($J6="","",VLOOKUP($J6,Prices!$A$2:$D$174,3,0))*$K6),"") -> 331 | P6: =IF(OR($L6="",$M6=""),"",($M6+$N6)/2-($L6-0.1*'Top 8'!$J$5*$O6)) -> 103.6 | Q6: =IF($P6="","",$P6*6000) -> 621600 | R6: =IF($P6="","",$P6+ROW()/1000000) -> 103.60001
A7: Compost potion(4) | B7: 22 | C7: 60 | D7: harralander potion (unf) | E7: 1 | F7: Volcanic ash | G7: 1 | L7: =IFERROR((IF($D7="","",VLOOKUP($D7,Prices!$A$2:$D$174,3,0))*$E7)+(IF($F7="","",VLOOKUP($F7,Prices!$A$2:$D$174,3,0))*$G7),"") -> 707 | M7: =IFERROR(VLOOKUP($A7,Prices!$A$2:$D$174,4,0),"") -> 2 | N7: =IF(ISNUMBER(SEARCH("(4)",$A7)),IFERROR(VLOOKUP(SUBSTITUTE($A7,"(4)","(2)"),Prices!$A$2:$D$174,4,0),""),"") -> 30 | O7: =IFERROR((IF($F7="","",VLOOKUP($F7,Prices!$A$2:$D$174,3,0))*$G7),"") -> 165 | P7: =IF(OR($L7="",$M7=""),"",(3+0.15*'Top 8'!$J$4)*($M7+$N7)/6-($L7-0.1*'Top 8'!$J$5*$O7)) -> -673.7 | Q7: =IF($P7="","",$P7*3000) -> -2021100 | R7: =IF($P7="","",$P7+ROW()/1000000) -> -673.69999
A8: Restore potion(4) | B8: 22 | C8: 62.5 | D8: harralander potion (unf) | E8: 1 | F8: Red spiders' eggs | G8: 1 | L8: =IFERROR((IF($D8="","",VLOOKUP($D8,Prices!$A$2:$D$174,3,0))*$E8)+(IF($F8="","",VLOOKUP($F8,Prices!$A$2:$D$174,3,0))*$G8),"") -> 726 | M8: =IFERROR(VLOOKUP($A8,Prices!$A$2:$D$174,4,0),"") -> 56 | N8: =IF(ISNUMBER(SEARCH("(4)",$A8)),IFERROR(VLOOKUP(SUBSTITUTE($A8,"(4)","(2)"),Prices!$A$2:$D$174,4,0),""),"") -> 44 | O8: =IFERROR((IF($F8="","",VLOOKUP($F8,Prices!$A$2:$D$174,3,0))*$G8),"") -> 184 | P8: =IF(OR($L8="",$M8=""),"",(3+0.15*'Top 8'!$J$4)*($M8+$N8)/6-($L8-0.1*'Top 8'!$J$5*$O8)) -> -655.1 | Q8: =IF($P8="","",$P8*3000) -> -1965300 | R8: =IF($P8="","",$P8+ROW()/1000000) -> -655.09999
A9: Guthix balance(4) | B9: 22 | C9: 50 | D9: Restore potion(4) | E9: 1 | F9: Garlic | G9: 1 | H9: Silver dust | I9: 1 | L9: =IFERROR((IF($D9="","",VLOOKUP($D9,Prices!$A$2:$D$174,3,0))*$E9)+(IF($F9="","",VLOOKUP($F9,Prices!$A$2:$D$174,3,0))*$G9)+(IF($H9="","",VLOOKUP($H9,Prices!$A$2:$D$174,3,0))*$I9)-0.25*((IF($D9="","",VLOOKUP($D9,Prices!$A$2:$D$174,3,0))*$E9)),"") -> 826.75 | M9: =IFERROR(VLOOKUP($A9,Prices!$A$2:$D$174,4,0),"") -> 1124 | N9: =IF(ISNUMBER(SEARCH("(4)",$A9)),IFERROR(VLOOKUP(SUBSTITUTE($A9,"(4)","(2)"),Prices!$A$2:$D$174,4,0),""),"") -> 512 | O9: =IFERROR((IF($F9="","",VLOOKUP($F9,Prices!$A$2:$D$174,3,0))*$G9)+(IF($H9="","",VLOOKUP($H9,Prices!$A$2:$D$174,3,0))*$I9),"") -> 784 | P9: =IF(OR($L9="",$M9=""),"",(3+0.15*'Top 8'!$J$4)*($M9+$N9)/6-($L9-0.1*'Top 8'!$J$5*$O9)) -> 110.55 | Q9: =IF($P9="","",$P9*3000) -> 331650 | R9: =IF($P9="","",$P9+ROW()/1000000) -> 110.55001
A10: Energy potion(4) | B10: 26 | C10: 67.5 | D10: harralander potion (unf) | E10: 1 | F10: Chocolate dust | G10: 1 | L10: =IFERROR((IF($D10="","",VLOOKUP($D10,Prices!$A$2:$D$174,3,0))*$E10)+(IF($F10="","",VLOOKUP($F10,Prices!$A$2:$D$174,3,0))*$G10),"") -> 598 | M10: =IFERROR(VLOOKUP($A10,Prices!$A$2:$D$174,4,0),"") -> 171 | N10: =IF(ISNUMBER(SEARCH("(4)",$A10)),IFERROR(VLOOKUP(SUBSTITUTE($A10,"(4)","(2)"),Prices!$A$2:$D$174,4,0),""),"") -> 84 | O10: =IFERROR((IF($F10="","",VLOOKUP($F10,Prices!$A$2:$D$174,3,0))*$G10),"") -> 56 | P10: =IF(OR($L10="",$M10=""),"",(3+0.15*'Top 8'!$J$4)*($M10+$N10)/6-($L10-0.1*'Top 8'!$J$5*$O10)) -> -458.525 | Q10: =IF($P10="","",$P10*3000) -> -1375575 | R10: =IF($P10="","",$P10+ROW()/1000000) -> -458.52499
A11: Defence potion(4) | B11: 30 | C11: 75 | D11: ranarr potion (unf) | E11: 1 | F11: White berries | G11: 1 | L11: =IFERROR((IF($D11="","",VLOOKUP($D11,Prices!$A$2:$D$174,3,0))*$E11)+(IF($F11="","",VLOOKUP($F11,Prices!$A$2:$D$174,3,0))*$G11),"") -> 6848 | M11: =IFERROR(VLOOKUP($A11,Prices!$A$2:$D$174,4,0),"") -> 571 | N11: =IF(ISNUMBER(SEARCH("(4)",$A11)),IFERROR(VLOOKUP(SUBSTITUTE($A11,"(4)","(2)"),Prices!$A$2:$D$174,4,0),""),"") -> 336 | O11: =IFERROR((IF($F11="","",VLOOKUP($F11,Prices!$A$2:$D$174,3,0))*$G11),"") -> 675 | P11: =IF(OR($L11="",$M11=""),"",(3+0.15*'Top 8'!$J$4)*($M11+$N11)/6-($L11-0.1*'Top 8'!$J$5*$O11)) -> -6304.325 | Q11: =IF($P11="","",$P11*3000) -> -18912975 | R11: =IF($P11="","",$P11+ROW()/1000000) -> -6304.325
A12: Agility potion(4) | B12: 34 | C12: 80 | D12: toadflax potion (unf) | E12: 1 | F12: Toad's legs | G12: 1 | L12: =IFERROR((IF($D12="","",VLOOKUP($D12,Prices!$A$2:$D$174,3,0))*$E12)+(IF($F12="","",VLOOKUP($F12,Prices!$A$2:$D$174,3,0))*$G12),"") -> 2917 | M12: =IFERROR(VLOOKUP($A12,Prices!$A$2:$D$174,4,0),"") -> 350 | N12: =IF(ISNUMBER(SEARCH("(4)",$A12)),IFERROR(VLOOKUP(SUBSTITUTE($A12,"(4)","(2)"),Prices!$A$2:$D$174,4,0),""),"") -> 206 | O12: =IFERROR((IF($F12="","",VLOOKUP($F12,Prices!$A$2:$D$174,3,0))*$G12),"") -> 327 | P12: =IF(OR($L12="",$M12=""),"",(3+0.15*'Top 8'!$J$4)*($M12+$N12)/6-($L12-0.1*'Top 8'!$J$5*$O12)) -> -2592.4 | Q12: =IF($P12="","",$P12*3000) -> -7777200 | R12: =IF($P12="","",$P12+ROW()/1000000) -> -2592.4
A13: Combat potion(4) | B13: 36 | C13: 84 | D13: harralander potion (unf) | E13: 1 | F13: Goat horn dust | G13: 1 | L13: =IFERROR((IF($D13="","",VLOOKUP($D13,Prices!$A$2:$D$174,3,0))*$E13)+(IF($F13="","",VLOOKUP($F13,Prices!$A$2:$D$174,3,0))*$G13),"") -> 672 | M13: =IFERROR(VLOOKUP($A13,Prices!$A$2:$D$174,4,0),"") -> 156 | N13: =IF(ISNUMBER(SEARCH("(4)",$A13)),IFERROR(VLOOKUP(SUBSTITUTE($A13,"(4)","(2)"),Prices!$A$2:$D$174,4,0),""),"") -> 158 | O13: =IFERROR((IF($F13="","",VLOOKUP($F13,Prices!$A$2:$D$174,3,0))*$G13),"") -> 130 | P13: =IF(OR($L13="",$M13=""),"",(3+0.15*'Top 8'!$J$4)*($M13+$N13)/6-($L13-0.1*'Top 8'!$J$5*$O13)) -> -494.15 | Q13: =IF($P13="","",$P13*3000) -> -1482450 | R13: =IF($P13="","",$P13+ROW()/1000000) -> -494.14999
A14: Prayer potion(4) | B14: 38 | C14: 87.5 | D14: ranarr potion (unf) | E14: 1 | F14: Snape grass | G14: 1 | L14: =IFERROR((IF($D14="","",VLOOKUP($D14,Prices!$A$2:$D$174,3,0))*$E14)+(IF($F14="","",VLOOKUP($F14,Prices!$A$2:$D$174,3,0))*$G14),"") -> 7170 | M14: =IFERROR(VLOOKUP($A14,Prices!$A$2:$D$174,4,0),"") -> 9473 | N14: =IF(ISNUMBER(SEARCH("(4)",$A14)),IFERROR(VLOOKUP(SUBSTITUTE($A14,"(4)","(2)"),Prices!$A$2:$D$174,4,0),""),"") -> 4526 | O14: =IFERROR((IF($F14="","",VLOOKUP($F14,Prices!$A$2:$D$174,3,0))*$G14),"") -> 997 | P14: =IF(OR($L14="",$M14=""),"",(3+0.15*'Top 8'!$J$4)*($M14+$N14)/6-($L14-0.1*'Top 8'!$J$5*$O14)) -> 279.175 | Q14: =IF($P14="","",$P14*3000) -> 837525 | R14: =IF($P14="","",$P14+ROW()/1000000) -> 279.17501
A15: Super attack(4) | B15: 45 | C15: 100 | D15: irit potion (unf) | E15: 1 | F15: Eye of newt | G15: 1 | L15: =IFERROR((IF($D15="","",VLOOKUP($D15,Prices!$A$2:$D$174,3,0))*$E15)+(IF($F15="","",VLOOKUP($F15,Prices!$A$2:$D$174,3,0))*$G15),"") -> 1735 | M15: =IFERROR(VLOOKUP($A15,Prices!$A$2:$D$174,4,0),"") -> 1885 | N15: =IF(ISNUMBER(SEARCH("(4)",$A15)),IFERROR(VLOOKUP(SUBSTITUTE($A15,"(4)","(2)"),Prices!$A$2:$D$174,4,0),""),"") -> 906 | O15: =IFERROR((IF($F15="","",VLOOKUP($F15,Prices!$A$2:$D$174,3,0))*$G15),"") -> 4 | P15: =IF(OR($L15="",$M15=""),"",(3+0.15*'Top 8'!$J$4)*($M15+$N15)/6-($L15-0.1*'Top 8'!$J$5*$O15)) -> -269.325 | Q15: =IF($P15="","",$P15*3000) -> -807975 | R15: =IF($P15="","",$P15+ROW()/1000000) -> -269.32498
A16: Superantipoison(4) | B16: 48 | C16: 106.25 | D16: irit potion (unf) | E16: 1 | F16: Unicorn horn dust | G16: 1 | L16: =IFERROR((IF($D16="","",VLOOKUP($D16,Prices!$A$2:$D$174,3,0))*$E16)+(IF($F16="","",VLOOKUP($F16,Prices!$A$2:$D$174,3,0))*$G16),"") -> 2430 | M16: =IFERROR(VLOOKUP($A16,Prices!$A$2:$D$174,4,0),"") -> 1352 | N16: =IF(ISNUMBER(SEARCH("(4)",$A16)),IFERROR(VLOOKUP(SUBSTITUTE($A16,"(4)","(2)"),Prices!$A$2:$D$174,4,0),""),"") -> 674 | O16: =IFERROR((IF($F16="","",VLOOKUP($F16,Prices!$A$2:$D$174,3,0))*$G16),"") -> 699 | P16: =IF(OR($L16="",$M16=""),"",(3+0.15*'Top 8'!$J$4)*($M16+$N16)/6-($L16-0.1*'Top 8'!$J$5*$O16)) -> -1296.45 | Q16: =IF($P16="","",$P16*3000) -> -3889350 | R16: =IF($P16="","",$P16+ROW()/1000000) -> -1296.45
A17: Fishing potion(4) | B17: 50 | C17: 112.5 | D17: avantoe potion (unf) | E17: 1 | F17: Snape grass | G17: 1 | L17: =IFERROR((IF($D17="","",VLOOKUP($D17,Prices!$A$2:$D$174,3,0))*$E17)+(IF($F17="","",VLOOKUP($F17,Prices!$A$2:$D$174,3,0))*$G17),"") -> 3464 | M17: =IFERROR(VLOOKUP($A17,Prices!$A$2:$D$174,4,0),"") -> 83 | N17: =IF(ISNUMBER(SEARCH("(4)",$A17)),IFERROR(VLOOKUP(SUBSTITUTE($A17,"(4)","(2)"),Prices!$A$2:$D$174,4,0),""),"") -> 75 | O17: =IFERROR((IF($F17="","",VLOOKUP($F17,Prices!$A$2:$D$174,3,0))*$G17),"") -> 997 | P17: =IF(OR($L17="",$M17=""),"",(3+0.15*'Top 8'!$J$4)*($M17+$N17)/6-($L17-0.1*'Top 8'!$J$5*$O17)) -> -3281.35 | Q17: =IF($P17="","",$P17*3000) -> -9844050 | R17: =IF($P17="","",$P17+ROW()/1000000) -> -3281.35
A18: Super energy(4) | B18: 52 | C18: 117.5 | D18: avantoe potion (unf) | E18: 1 | F18: Mort myre fungus | G18: 1 | L18: =IFERROR((IF($D18="","",VLOOKUP($D18,Prices!$A$2:$D$174,3,0))*$E18)+(IF($F18="","",VLOOKUP($F18,Prices!$A$2:$D$174,3,0))*$G18),"") -> 2687 | M18: =IFERROR(VLOOKUP($A18,Prices!$A$2:$D$174,4,0),"") -> 2566 | N18: =IF(ISNUMBER(SEARCH("(4)",$A18)),IFERROR(VLOOKUP(SUBSTITUTE($A18,"(4)","(2)"),Prices!$A$2:$D$174,4,0),""),"") -> 1723 | O18: =IFERROR((IF($F18="","",VLOOKUP($F18,Prices!$A$2:$D$174,3,0))*$G18),"") -> 220 | P18: =IF(OR($L18="",$M18=""),"",(3+0.15*'Top 8'!$J$4)*($M18+$N18)/6-($L18-0.1*'Top 8'!$J$5*$O18)) -> -413.275 | Q18: =IF($P18="","",$P18*3000) -> -1239825 | R18: =IF($P18="","",$P18+ROW()/1000000) -> -413.27498
A19: Hunter potion(4) | B19: 53 | C19: 120 | D19: avantoe potion (unf) | E19: 1 | F19: Kebbit teeth dust | G19: 1 | L19: =IFERROR((IF($D19="","",VLOOKUP($D19,Prices!$A$2:$D$174,3,0))*$E19)+(IF($F19="","",VLOOKUP($F19,Prices!$A$2:$D$174,3,0))*$G19),"") -> 3232 | M19: =IFERROR(VLOOKUP($A19,Prices!$A$2:$D$174,4,0),"") -> 560 | N19: =IF(ISNUMBER(SEARCH("(4)",$A19)),IFERROR(VLOOKUP(SUBSTITUTE($A19,"(4)","(2)"),Prices!$A$2:$D$174,4,0),""),"") -> 1154 | O19: =IFERROR((IF($F19="","",VLOOKUP($F19,Prices!$A$2:$D$174,3,0))*$G19),"") -> 765 | P19: =IF(OR($L19="",$M19=""),"",(3+0.15*'Top 8'!$J$4)*($M19+$N19)/6-($L19-0.1*'Top 8'!$J$5*$O19)) -> -2255.65 | Q19: =IF($P19="","",$P19*3000) -> -6766950 | R19: =IF($P19="","",$P19+ROW()/1000000) -> -2255.65
A20: Goading potion(4) | B20: 54 | C20: 132 | D20: harralander potion (unf) | E20: 1 | F20: Aldarium | G20: 1 | L20: =IFERROR((IF($D20="","",VLOOKUP($D20,Prices!$A$2:$D$174,3,0))*$E20)+(IF($F20="","",VLOOKUP($F20,Prices!$A$2:$D$174,3,0))*$G20),"") -> 49560 | M20: =IFERROR(VLOOKUP($A20,Prices!$A$2:$D$174,4,0),"") -> 58337 | N20: =IF(ISNUMBER(SEARCH("(4)",$A20)),IFERROR(VLOOKUP(SUBSTITUTE($A20,"(4)","(2)"),Prices!$A$2:$D$174,4,0),""),"") -> 31237 | O20: =IFERROR((IF($F20="","",VLOOKUP($F20,Prices!$A$2:$D$174,3,0))*$G20),"") -> 49018 | P20: =IF(OR($L20="",$M20=""),"",(3+0.15*'Top 8'!$J$4)*($M20+$N20)/6-($L20-0.1*'Top 8'!$J$5*$O20)) -> 2368.15 | Q20: =IF($P20="","",$P20*3000) -> 7104450 | R20: =IF($P20="","",$P20+ROW()/1000000) -> 2368.15
A21: Super strength(4) | B21: 55 | C21: 125 | D21: kwuarm potion (unf) | E21: 1 | F21: Limpwurt root | G21: 1 | L21: =IFERROR((IF($D21="","",VLOOKUP($D21,Prices!$A$2:$D$174,3,0))*$E21)+(IF($F21="","",VLOOKUP($F21,Prices!$A$2:$D$174,3,0))*$G21),"") -> 2831 | M21: =IFERROR(VLOOKUP($A21,Prices!$A$2:$D$174,4,0),"") -> 3039 | N21: =IF(ISNUMBER(SEARCH("(4)",$A21)),IFERROR(VLOOKUP(SUBSTITUTE($A21,"(4)","(2)"),Prices!$A$2:$D$174,4,0),""),"") -> 1451 | O21: =IFERROR((IF($F21="","",VLOOKUP($F21,Prices!$A$2:$D$174,3,0))*$G21),"") -> 221 | P21: =IF(OR($L21="",$M21=""),"",(3+0.15*'Top 8'!$J$4)*($M21+$N21)/6-($L21-0.1*'Top 8'!$J$5*$O21)) -> -451.65 | Q21: =IF($P21="","",$P21*3000) -> -1354950 | R21: =IF($P21="","",$P21+ROW()/1000000) -> -451.64998
A22: Haemostatic poultice | B22: 56 | C22: 27 | D22: elkhorn potion (unf) | E22: 1 | F22: Squid paste | G22: 1 | L22: =IFERROR((IF($D22="","",VLOOKUP($D22,Prices!$A$2:$D$174,3,0))*$E22)+(IF($F22="","",VLOOKUP($F22,Prices!$A$2:$D$174,3,0))*$G22),"") -> 2411 | M22: =IFERROR(VLOOKUP($A22,Prices!$A$2:$D$174,4,0),"") -> 3154 | N22: =IF(ISNUMBER(SEARCH("(4)",$A22)),IFERROR(VLOOKUP(SUBSTITUTE($A22,"(4)","(2)"),Prices!$A$2:$D$174,4,0),""),"") | O22: =IFERROR((IF($F22="","",VLOOKUP($F22,Prices!$A$2:$D$174,3,0))*$G22),"") -> 1211 | P22: =IF(OR($L22="",$M22=""),"",$M22-($L22-0.1*'Top 8'!$J$5*$O22)) -> 864.1 | Q22: =IF($P22="","",$P22*3000) -> 2592300 | R22: =IF($P22="","",$P22+ROW()/1000000) -> 864.10002
A23: Haemostatic dressing (4) | B23: 56 | C23: 100 | D23: Haemostatic poultice | E23: 1 | F23: Cotton yarn | G23: 1 | L23: =IFERROR((IF($D23="","",VLOOKUP($D23,Prices!$A$2:$D$174,3,0))*$E23)+(IF($F23="","",VLOOKUP($F23,Prices!$A$2:$D$174,3,0))*$G23),"") -> 5155 | M23: =IFERROR(VLOOKUP($A23,Prices!$A$2:$D$174,4,0),"") -> 6328 | N23: =IF(ISNUMBER(SEARCH("(4)",$A23)),IFERROR(VLOOKUP(SUBSTITUTE($A23,"(4)","(2)"),Prices!$A$2:$D$174,4,0),""),"") -> 2793 | O23: =IFERROR((IF($F23="","",VLOOKUP($F23,Prices!$A$2:$D$174,3,0))*$G23),"") -> 1937 | P23: =IF(OR($L23="",$M23=""),"",(3+0.15*'Top 8'!$J$4)*($M23+$N23)/6-($L23-0.1*'Top 8'!$J$5*$O23)) -> -172.775 | Q23: =IF($P23="","",$P23*3000) -> -518325 | R23: =IF($P23="","",$P23+ROW()/1000000) -> -172.77498
A24: Prayer regeneration potion(4) | B24: 58 | C24: 132 | D24: huasca potion (unf) | E24: 1 | F24: Aldarium | G24: 1 | L24: =IFERROR((IF($D24="","",VLOOKUP($D24,Prices!$A$2:$D$174,3,0))*$E24)+(IF($F24="","",VLOOKUP($F24,Prices!$A$2:$D$174,3,0))*$G24),"") -> 57078 | M24: =IFERROR(VLOOKUP($A24,Prices!$A$2:$D$174,4,0),"") -> 68159 | N24: =IF(ISNUMBER(SEARCH("(4)",$A24)),IFERROR(VLOOKUP(SUBSTITUTE($A24,"(4)","(2)"),Prices!$A$2:$D$174,4,0),""),"") -> 36398 | O24: =IFERROR((IF($F24="","",VLOOKUP($F24,Prices!$A$2:$D$174,3,0))*$G24),"") -> 49018 | P24: =IF(OR($L24="",$M24=""),"",(3+0.15*'Top 8'!$J$4)*($M24+$N24)/6-($L24-0.1*'Top 8'!$J$5*$O24)) -> 2716.225 | Q24: =IF($P24="","",$P24*3000) -> 8148675 | R24: =IF($P24="","",$P24+ROW()/1000000) -> 2716.225
A25: Weapon poison | B25: 60 | C25: 137.5 | D25: kwuarm potion (unf) | E25: 1 | F25: Dragon scale dust | G25: 1 | L25: =IFERROR((IF($D25="","",VLOOKUP($D25,Prices!$A$2:$D$174,3,0))*$E25)+(IF($F25="","",VLOOKUP($F25,Prices!$A$2:$D$174,3,0))*$G25),"") -> 2680 | M25: =IFERROR(VLOOKUP($A25,Prices!$A$2:$D$174,4,0),"") -> 280 | N25: =IF(ISNUMBER(SEARCH("(4)",$A25)),IFERROR(VLOOKUP(SUBSTITUTE($A25,"(4)","(2)"),Prices!$A$2:$D$174,4,0),""),"") | O25: =IFERROR((IF($F25="","",VLOOKUP($F25,Prices!$A$2:$D$174,3,0))*$G25),"") -> 70 | P25: =IF(OR($L25="",$M25=""),"",$M25-($L25-0.1*'Top 8'!$J$5*$O25)) -> -2393 | Q25: =IF($P25="","",$P25*3000) -> -7179000 | R25: =IF($P25="","",$P25+ROW()/1000000) -> -2393
A26: Super fishing potion(4) | B26: 62 | C26: 140.5 | D26: pillar potion (unf) | E26: 1 | F26: Haddock eye | G26: 1 | L26: =IFERROR((IF($D26="","",VLOOKUP($D26,Prices!$A$2:$D$174,3,0))*$E26)+(IF($F26="","",VLOOKUP($F26,Prices!$A$2:$D$174,3,0))*$G26),"") -> 2701 | M26: =IFERROR(VLOOKUP($A26,Prices!$A$2:$D$174,4,0),"") -> 1875 | N26: =IF(ISNUMBER(SEARCH("(4)",$A26)),IFERROR(VLOOKUP(SUBSTITUTE($A26,"(4)","(2)"),Prices!$A$2:$D$174,4,0),""),"") -> 2052 | O26: =IFERROR((IF($F26="","",VLOOKUP($F26,Prices!$A$2:$D$174,3,0))*$G26),"") -> 90 | P26: =IF(OR($L26="",$M26=""),"",(3+0.15*'Top 8'!$J$4)*($M26+$N26)/6-($L26-0.1*'Top 8'!$J$5*$O26)) -> -630.325 | Q26: =IF($P26="","",$P26*3000) -> -1890975 | R26: =IF($P26="","",$P26+ROW()/1000000) -> -630.32497
A27: Super restore(4) | B27: 63 | C27: 142.5 | D27: snapdragon potion (unf) | E27: 1 | F27: Red spiders' eggs | G27: 1 | L27: =IFERROR((IF($D27="","",VLOOKUP($D27,Prices!$A$2:$D$174,3,0))*$E27)+(IF($F27="","",VLOOKUP($F27,Prices!$A$2:$D$174,3,0))*$G27),"") -> 8084 | M27: =IFERROR(VLOOKUP($A27,Prices!$A$2:$D$174,4,0),"") -> 9810 | N27: =IF(ISNUMBER(SEARCH("(4)",$A27)),IFERROR(VLOOKUP(SUBSTITUTE($A27,"(4)","(2)"),Prices!$A$2:$D$174,4,0),""),"") -> 4789 | O27: =IFERROR((IF($F27="","",VLOOKUP($F27,Prices!$A$2:$D$174,3,0))*$G27),"") -> 184 | P27: =IF(OR($L27="",$M27=""),"",(3+0.15*'Top 8'!$J$4)*($M27+$N27)/6-($L27-0.1*'Top 8'!$J$5*$O27)) -> -401.125 | Q27: =IF($P27="","",$P27*3000) -> -1203375 | R27: =IF($P27="","",$P27+ROW()/1000000) -> -401.12497
A28: Sanfew serum(4) | B28: 65 | C28: 160 | D28: Super restore(4) | E28: 1 | F28: Unicorn horn dust | G28: 1 | H28: Clean snake weed | I28: 1 | J28: Nail beast nails | K28: 1 | L28: =IFERROR((IF($D28="","",VLOOKUP($D28,Prices!$A$2:$D$174,3,0))*$E28)+(IF($F28="","",VLOOKUP($F28,Prices!$A$2:$D$174,3,0))*$G28)+(IF($H28="","",VLOOKUP($H28,Prices!$A$2:$D$174,3,0))*$I28)+(IF($J28="","",VLOOKUP($J28,Prices!$A$2:$D$174,3,0))*$K28)-0.25*((IF($D28="","",VLOOKUP($D28,Prices!$A$2:$D$174,3,0))*$E28)),"") | M28: =IFERROR(VLOOKUP($A28,Prices!$A$2:$D$174,4,0),"") -> 19090 | N28: =IF(ISNUMBER(SEARCH("(4)",$A28)),IFERROR(VLOOKUP(SUBSTITUTE($A28,"(4)","(2)"),Prices!$A$2:$D$174,4,0),""),"") -> 8335 | O28: =IFERROR((IF($F28="","",VLOOKUP($F28,Prices!$A$2:$D$174,3,0))*$G28)+(IF($H28="","",VLOOKUP($H28,Prices!$A$2:$D$174,3,0))*$I28)+(IF($J28="","",VLOOKUP($J28,Prices!$A$2:$D$174,3,0))*$K28),"") | P28: =IF(OR($L28="",$M28=""),"",(3+0.15*'Top 8'!$J$4)*($M28+$N28)/6-($L28-0.1*'Top 8'!$J$5*$O28)) | Q28: =IF($P28="","",$P28*3000) | R28: =IF($P28="","",$P28+ROW()/1000000)
A29: Extreme energy potion(4) | B29: 66 | C29: 84 | D29: Super energy(4) | E29: 1 | F29: Yellow fin | G29: 4 | L29: =IFERROR(0.75*((IF($D29="","",VLOOKUP($D29,Prices!$A$2:$D$174,3,0))*$E29)+(IF($F29="","",VLOOKUP($F29,Prices!$A$2:$D$174,3,0))*$G29)),"") -> 2524.5 | M29: =IFERROR(VLOOKUP($A29,Prices!$A$2:$D$174,4,0),"") -> 2250 | N29: =IF(ISNUMBER(SEARCH("(4)",$A29)),IFERROR(VLOOKUP(SUBSTITUTE($A29,"(4)","(2)"),Prices!$A$2:$D$174,4,0),""),"") -> 2331 | O29: =IFERROR(0.75*((IF($F29="","",VLOOKUP($F29,Prices!$A$2:$D$174,3,0))*$G29)),"") -> 561 | P29: =IF(OR($L29="",$M29=""),"",(3+0.15*'Top 8'!$J$4)*($M29+$N29)/6-($L29-0.1*'Top 8'!$J$5*$O29)) -> -63.375 | Q29: =IF($P29="","",$P29*3000) -> -190125 | R29: =IF($P29="","",$P29+ROW()/1000000) -> -63.37497
A30: Super defence(4) | B30: 66 | C30: 150 | D30: cadantine potion (unf) | E30: 1 | F30: White berries | G30: 1 | L30: =IFERROR((IF($D30="","",VLOOKUP($D30,Prices!$A$2:$D$174,3,0))*$E30)+(IF($F30="","",VLOOKUP($F30,Prices!$A$2:$D$174,3,0))*$G30),"") -> 3245 | M30: =IFERROR(VLOOKUP($A30,Prices!$A$2:$D$174,4,0),"") -> 3073 | N30: =IF(ISNUMBER(SEARCH("(4)",$A30)),IFERROR(VLOOKUP(SUBSTITUTE($A30,"(4)","(2)"),Prices!$A$2:$D$174,4,0),""),"") -> 1537 | O30: =IFERROR((IF($F30="","",VLOOKUP($F30,Prices!$A$2:$D$174,3,0))*$G30),"") -> 675 | P30: =IF(OR($L30="",$M30=""),"",(3+0.15*'Top 8'!$J$4)*($M30+$N30)/6-($L30-0.1*'Top 8'!$J$5*$O30)) -> -757.25 | Q30: =IF($P30="","",$P30*3000) -> -2271750 | R30: =IF($P30="","",$P30+ROW()/1000000) -> -757.24997
A31: Super hunter potion(4) | B31: 67 | C31: 154 | D31: pillar potion (unf) | E31: 1 | F31: Crab paste | G31: 1 | L31: =IFERROR((IF($D31="","",VLOOKUP($D31,Prices!$A$2:$D$174,3,0))*$E31)+(IF($F31="","",VLOOKUP($F31,Prices!$A$2:$D$174,3,0))*$G31),"") -> 2694 | M31: =IFERROR(VLOOKUP($A31,Prices!$A$2:$D$174,4,0),"") -> 760 | N31: =IF(ISNUMBER(SEARCH("(4)",$A31)),IFERROR(VLOOKUP(SUBSTITUTE($A31,"(4)","(2)"),Prices!$A$2:$D$174,4,0),""),"") -> 2166 | O31: =IFERROR((IF($F31="","",VLOOKUP($F31,Prices!$A$2:$D$174,3,0))*$G31),"") -> 83 | P31: =IF(OR($L31="",$M31=""),"",(3+0.15*'Top 8'!$J$4)*($M31+$N31)/6-($L31-0.1*'Top 8'!$J$5*$O31)) -> -1149.55 | Q31: =IF($P31="","",$P31*3000) -> -3448650 | R31: =IF($P31="","",$P31+ROW()/1000000) -> -1149.55
A32: Antidote+(4) | B32: 68 | C32: 155 | D32: Coconut milk | E32: 1 | F32: Toadflax | G32: 1 | H32: Yew roots | I32: 1 | L32: =IFERROR((IF($D32="","",VLOOKUP($D32,Prices!$A$2:$D$174,3,0))*$E32)+(IF($F32="","",VLOOKUP($F32,Prices!$A$2:$D$174,3,0))*$G32)+(IF($H32="","",VLOOKUP($H32,Prices!$A$2:$D$174,3,0))*$I32),"") -> 2619 | M32: =IFERROR(VLOOKUP($A32,Prices!$A$2:$D$174,4,0),"") -> 1608 | N32: =IF(ISNUMBER(SEARCH("(4)",$A32)),IFERROR(VLOOKUP(SUBSTITUTE($A32,"(4)","(2)"),Prices!$A$2:$D$174,4,0),""),"") -> 1297 | O32: =IFERROR((IF($H32="","",VLOOKUP($H32,Prices!$A$2:$D$174,3,0))*$I32),"") -> 71 | P32: =IF(OR($L32="",$M32=""),"",$M32-($L32-0.1*'Top 8'!$J$5*$O32)) -> -1003.9 | Q32: =IF($P32="","",$P32*3000) -> -3011700 | R32: =IF($P32="","",$P32+ROW()/1000000) -> -1003.9
A33: Antifire potion(4) | B33: 69 | C33: 157.5 | D33: lantadyme potion (unf) | E33: 1 | F33: Dragon scale dust | G33: 1 | L33: =IFERROR((IF($D33="","",VLOOKUP($D33,Prices!$A$2:$D$174,3,0))*$E33)+(IF($F33="","",VLOOKUP($F33,Prices!$A$2:$D$174,3,0))*$G33),"") -> 1754 | M33: =IFERROR(VLOOKUP($A33,Prices!$A$2:$D$174,4,0),"") -> 870 | N33: =IF(ISNUMBER(SEARCH("(4)",$A33)),IFERROR(VLOOKUP(SUBSTITUTE($A33,"(4)","(2)"),Prices!$A$2:$D$174,4,0),""),"") -> 505 | O33: =IFERROR((IF($F33="","",VLOOKUP($F33,Prices!$A$2:$D$174,3,0))*$G33),"") -> 70 | P33: =IF(OR($L33="",$M33=""),"",(3+0.15*'Top 8'!$J$4)*($M33+$N33)/6-($L33-0.1*'Top 8'!$J$5*$O33)) -> -1025.125 | Q33: =IF($P33="","",$P33*3000) -> -3075375 | R33: =IF($P33="","",$P33+ROW()/1000000) -> -1025.125
A34: Ranging potion(4) | B34: 72 | C34: 162.5 | D34: dwarf weed potion (unf) | E34: 1 | F34: Wine of Zamorak | G34: 1 | L34: =IFERROR((IF($D34="","",VLOOKUP($D34,Prices!$A$2:$D$174,3,0))*$E34)+(IF($F34="","",VLOOKUP($F34,Prices!$A$2:$D$174,3,0))*$G34),"") -> 2604 | M34: =IFERROR(VLOOKUP($A34,Prices!$A$2:$D$174,4,0),"") -> 1718 | N34: =IF(ISNUMBER(SEARCH("(4)",$A34)),IFERROR(VLOOKUP(SUBSTITUTE($A34,"(4)","(2)"),Prices!$A$2:$D$174,4,0),""),"") -> 908 | O34: =IFERROR((IF($F34="","",VLOOKUP($F34,Prices!$A$2:$D$174,3,0))*$G34),"") -> 924 | P34: =IF(OR($L34="",$M34=""),"",(3+0.15*'Top 8'!$J$4)*($M34+$N34)/6-($L34-0.1*'Top 8'!$J$5*$O34)) -> -1132.95 | Q34: =IF($P34="","",$P34*3000) -> -3398850 | R34: =IF($P34="","",$P34+ROW()/1000000) -> -1132.95
A35: Weapon poison(+) | B35: 73 | C35: 190 | D35: Coconut milk | E35: 1 | F35: Cactus spine | G35: 1 | H35: Red spiders' eggs | I35: 1 | L35: =IFERROR((IF($D35="","",VLOOKUP($D35,Prices!$A$2:$D$174,3,0))*$E35)+(IF($F35="","",VLOOKUP($F35,Prices!$A$2:$D$174,3,0))*$G35)+(IF($H35="","",VLOOKUP($H35,Prices!$A$2:$D$174,3,0))*$I35),"") -> 2056 | M35: =IFERROR(VLOOKUP($A35,Prices!$A$2:$D$174,4,0),"") -> 898 | N35: =IF(ISNUMBER(SEARCH("(4)",$A35)),IFERROR(VLOOKUP(SUBSTITUTE($A35,"(4)","(2)"),Prices!$A$2:$D$174,4,0),""),"") | O35: =IFERROR((IF($H35="","",VLOOKUP($H35,Prices!$A$2:$D$174,3,0))*$I35),"") -> 184 | P35: =IF(OR($L35="",$M35=""),"",$M35-($L35-0.1*'Top 8'!$J$5*$O35)) -> -1139.6 | Q35: =IF($P35="","",$P35*3000) -> -3418800 | R35: =IF($P35="","",$P35+ROW()/1000000) -> -1139.6
A36: Magic potion(4) | B36: 76 | C36: 172.5 | D36: lantadyme potion (unf) | E36: 1 | F36: Potato cactus | G36: 1 | L36: =IFERROR((IF($D36="","",VLOOKUP($D36,Prices!$A$2:$D$174,3,0))*$E36)+(IF($F36="","",VLOOKUP($F36,Prices!$A$2:$D$174,3,0))*$G36),"") -> 1749 | M36: =IFERROR(VLOOKUP($A36,Prices!$A$2:$D$174,4,0),"") -> 124 | N36: =IF(ISNUMBER(SEARCH("(4)",$A36)),IFERROR(VLOOKUP(SUBSTITUTE($A36,"(4)","(2)"),Prices!$A$2:$D$174,4,0),""),"") -> 63 | O36: =IFERROR((IF($F36="","",VLOOKUP($F36,Prices!$A$2:$D$174,3,0))*$G36),"") -> 65 | P36: =IF(OR($L36="",$M36=""),"",(3+0.15*'Top 8'!$J$4)*($M36+$N36)/6-($L36-0.1*'Top 8'!$J$5*$O36)) -> -1644.325 | Q36: =IF($P36="","",$P36*3000) -> -4932975 | R36: =IF($P36="","",$P36+ROW()/1000000) -> -1644.325
A37: Stamina potion(4) | B37: 77 | C37: 102 | D37: Super energy(4) | E37: 1 | F37: Amylase crystal | G37: 4 | L37: =IFERROR(0.75*((IF($D37="","",VLOOKUP($D37,Prices!$A$2:$D$174,3,0))*$E37)+(IF($F37="","",VLOOKUP($F37,Prices!$A$2:$D$174,3,0))*$G37)),"") -> 3484.5 | M37: =IFERROR(VLOOKUP($A37,Prices!$A$2:$D$174,4,0),"") -> 3990 | N37: =IF(ISNUMBER(SEARCH("(4)",$A37)),IFERROR(VLOOKUP(SUBSTITUTE($A37,"(4)","(2)"),Prices!$A$2:$D$174,4,0),""),"") -> 1826 | O37: =IFERROR(0.75*((IF($F37="","",VLOOKUP($F37,Prices!$A$2:$D$174,3,0))*$G37)),"") -> 1521 | P37: =IF(OR($L37="",$M37=""),"",(3+0.15*'Top 8'!$J$4)*($M37+$N37)/6-($L37-0.1*'Top 8'!$J$5*$O37)) -> -279 | Q37: =IF($P37="","",$P37*3000) -> -837000 | R37: =IF($P37="","",$P37+ROW()/1000000) -> -278.99996
A38: Zamorak brew(4) | B38: 78 | C38: 175 | D38: torstol potion (unf) | E38: 1 | F38: Jangerberries | G38: 1 | L38: =IFERROR((IF($D38="","",VLOOKUP($D38,Prices!$A$2:$D$174,3,0))*$E38)+(IF($F38="","",VLOOKUP($F38,Prices!$A$2:$D$174,3,0))*$G38),"") -> 4248 | M38: =IFERROR(VLOOKUP($A38,Prices!$A$2:$D$174,4,0),"") -> 599 | N38: =IF(ISNUMBER(SEARCH("(4)",$A38)),IFERROR(VLOOKUP(SUBSTITUTE($A38,"(4)","(2)"),Prices!$A$2:$D$174,4,0),""),"") -> 506 | O38: =IFERROR((IF($F38="","",VLOOKUP($F38,Prices!$A$2:$D$174,3,0))*$G38),"") -> 329 | P38: =IF(OR($L38="",$M38=""),"",(3+0.15*'Top 8'!$J$4)*($M38+$N38)/6-($L38-0.1*'Top 8'!$J$5*$O38)) -> -3634.975 | Q38: =IF($P38="","",$P38*3000) -> -10904925 | R38: =IF($P38="","",$P38+ROW()/1000000) -> -3634.975
A39: Antidote++(4) | B39: 79 | C39: 177.5 | D39: Coconut milk | E39: 1 | F39: Irit leaf | G39: 1 | H39: Magic roots | I39: 1 | L39: =IFERROR((IF($D39="","",VLOOKUP($D39,Prices!$A$2:$D$174,3,0))*$E39)+(IF($F39="","",VLOOKUP($F39,Prices!$A$2:$D$174,3,0))*$G39)+(IF($H39="","",VLOOKUP($H39,Prices!$A$2:$D$174,3,0))*$I39),"") -> 9783 | M39: =IFERROR(VLOOKUP($A39,Prices!$A$2:$D$174,4,0),"") -> 8583 | N39: =IF(ISNUMBER(SEARCH("(4)",$A39)),IFERROR(VLOOKUP(SUBSTITUTE($A39,"(4)","(2)"),Prices!$A$2:$D$174,4,0),""),"") -> 3556 | O39: =IFERROR((IF($H39="","",VLOOKUP($H39,Prices!$A$2:$D$174,3,0))*$I39),"") -> 8034 | P39: =IF(OR($L39="",$M39=""),"",$M39-($L39-0.1*'Top 8'!$J$5*$O39)) -> -396.6 | Q39: =IF($P39="","",$P39*3000) -> -1189800 | R39: =IF($P39="","",$P39+ROW()/1000000) -> -396.59996
A40: Bastion potion(4) | B40: 80 | C40: 155 | D40: Vial of blood | E40: 1 | F40: Cadantine | G40: 1 | H40: Wine of Zamorak | I40: 1 | L40: =IFERROR((IF($D40="","",VLOOKUP($D40,Prices!$A$2:$D$174,3,0))*$E40)+(IF($F40="","",VLOOKUP($F40,Prices!$A$2:$D$174,3,0))*$G40)+(IF($H40="","",VLOOKUP($H40,Prices!$A$2:$D$174,3,0))*$I40),"") -> 11830 | M40: =IFERROR(VLOOKUP($A40,Prices!$A$2:$D$174,4,0),"") -> 15294 | N40: =IF(ISNUMBER(SEARCH("(4)",$A40)),IFERROR(VLOOKUP(SUBSTITUTE($A40,"(4)","(2)"),Prices!$A$2:$D$174,4,0),""),"") -> 6657 | O40: =IFERROR((IF($H40="","",VLOOKUP($H40,Prices!$A$2:$D$174,3,0))*$I40),"") -> 924 | P40: =IF(OR($L40="",$M40=""),"",(3+0.15*'Top 8'!$J$4)*($M40+$N40)/6-($L40-0.1*'Top 8'!$J$5*$O40)) -> -213.325 | Q40: =IF($P40="","",$P40*3000) -> -639975 | R40: =IF($P40="","",$P40+ROW()/1000000) -> -213.32496
...

Sheet Prices
A1: Item | B1: ID | C1: Buy price | D1: Sell price (after 2% GE tax) | E1: Last updated (UTC)
A2: Agility potion(2) | B2: 3036 | C2: 210 | D2: 206 | E2: 2026-09-15 03:03
A3: Agility potion(4) | B3: 3032 | C3: 357 | D3: 350 | E3: 2026-09-15 03:03
A4: Aldarium | B4: 29993 | C4: 49018 | D4: 48038 | E4: 2026-09-15 03:03
A5: Amylase crystal | B5: 12640 | C5: 507 | D5: 497 | E5: 2026-09-15 03:03
A6: Ancient brew(2) | B6: 26344 | C6: 1545 | D6: 1515 | E6: 2026-09-15 03:03
A7: Ancient brew(4) | B7: 26340 | C7: 2976 | D7: 2917 | E7: 2026-09-15 03:03
A8: Ancient essence | B8: 27616 | C8: 19 | D8: 19 | E8: 2026-09-15 03:03
A9: Anti-venom(2) | B9: 12909 | C9: 5140 | D9: 5038 | E9: 2026-09-15 03:03
A10: Anti-venom(4) | B10: 12905 | C10: 11007 | D10: 10787 | E10: 2026-09-15 03:03
A11: Anti-venom+(2) | B11: 12917 | C11: 7487 | D11: 7338 | E11: 2026-09-15 03:03
A12: Anti-venom+(4) | B12: 12913 | C12: 14617 | D12: 14325 | E12: 2026-09-15 03:03
A13: Antidote+(2) | B13: 5947 | C13: 1323 | D13: 1297 | E13: 2026-09-15 03:03
... A154: Superantipoison(4) | B154: 2448 | C154: 1379 | D154: 1352 | E154: 2026-09-15 03:03
A155: Surge potion(2) | B155: 30881
A156: tarromin potion (unf) | B156: 95 | C156: 484 | D156: 550 | E156: 2026-09-13 11:34
A157: Toad's legs | B157: 2152 | C157: 327 | D157: 321 | E157: 2026-09-15 03:03
A158: Toadflax | B158: 2998 | C158: 2289 | D158: 2244 | E158: 2026-09-15 03:03
A159: toadflax potion (unf) | B159: 3002 | C159: 2590 | D159: 2539 | E159: 2026-09-13 11:34
A160: Torstol | B160: 269 | C160: 3737 | D160: 3663 | E160: 2026-09-15 03:03
A161: torstol potion (unf) | B161: 111 | C161: 3919 | D161: 3885 | E161: 2026-09-13 11:34
A162: umbral potion (unf) | B162: 31668 | C162: 2742 | D162: 2659 | E162: 2026-09-13 11:34
A163: Unicorn horn dust | B163: 235 | C163: 699 | D163: 686 | E163: 2026-09-15 03:03
A164: Vial of blood | B164: 22446 | C164: 8639 | D164: 8467 | E164: 2026-09-15 03:03
A165: Volcanic ash | B165: 21622 | C165: 165 | D165: 162 | E165: 2026-09-15 03:03
A166: Weapon poison | B166: 187 | C166: 285 | D166: 280 | E166: 2026-09-15 03:03
A167: Weapon poison(+) | B167: 5937 | C167: 916 | D167: 898 | E167: 2026-09-15 03:03
... A174: Zulrah's scales | B174: 12934 | C174: 153 | D174: 150 | E174: 2026-09-15 03:03
